Workbook

Sheet Summary
A1: Portfolio risk analysis: VaR, Expected Shortfall and optimisation
A2: 9 Brazilian stocks, equal weights, daily data from 2019-08-30 to 2021-08-27. All figures below are live links to the calculation sheets.
B4: Metric | C4: Value | D4: Where it comes from
B5: Portfolio value (R$) | C5: =Inputs!$C$4 -> 1000000 | D5: Inputs
B6: Daily returns used | C6: =Risk_Metrics!C11 -> 491 | D6: Risk_Metrics
B7: Daily volatility, equal-weight portfolio | C7: =Risk_Metrics!C5 -> 0.02360074 | D7: Risk_Metrics
B8: VaR 95% (historical) | C8: =Risk_Metrics!C7 -> -0.025595079 | D8: Risk_Metrics
B9: VaR 95% (R$) | C9: =Risk_Metrics!C9 -> -25595.079 | D9: Risk_Metrics
B10: Expected Shortfall 95% | C10: =Risk_Metrics!C8 -> -0.060811559 | D10: Risk_Metrics
B11: Expected Shortfall 95% (R$) | C11: =Risk_Metrics!C10 -> -60811.559 | D11: Risk_Metrics
B12: VaR 95% excluding the crash window | C12: =Risk_Metrics!C20 -> -0.019974351 | D12: Risk_Metrics
B13: Expected Shortfall 95% excluding the crash window | C13: =Risk_Metrics!C21 -> -0.029953101 | D13: Risk_Metrics
B14: Share of days in the crash window | C14: =Risk_Metrics!C17 -> 0.093686354 | D14: Risk_Metrics
B15: Share of the worst 5% days inside the crash window | C15: =Risk_Metrics!C19 -> 0.56 | D15: Risk_Metrics
B16: Maximum drawdown (peak to trough) | C16: =Risk_Metrics!C27 -> -0.47234663 | D16: Risk_Metrics
B17: Average volatility of the 9 stocks | C17: =Risk_Metrics!D45 -> 0.032435973 | D17: Risk_Metrics
B18: Average pair correlation: full period | C18: =Correlation!C14 -> 0.4642649 | D18: Correlation
B19: Average pair correlation: excluding crash | C19: =Correlation!C28 -> 0.23267 | D19: Correlation
B20: Average pair correlation: crash window only | C20: =Correlation!C42 -> 0.72410121 | D20: Correlation
B21: Daily volatility, minimum-variance portfolio | C21: =Optimization!N8 -> 0.01978211 | D21: Optimization
B22: Volatility vs. equal weights | C22: =Optimization!O8 -> -0.16180126 | D22: Optimization
B23: Largest weight in the minimum-variance portfolio | C23: =Optimization!T8 -> 0.44864462 | D23: Optimization
B24: Daily volatility, 30% cap portfolio | C24: =Optimization!N9 -> 0.020146545 | D24: Optimization
B25: Out-of-sample volatility vs. equal weights | C25: =Optimization!D39 -> -0.10545501 | D25: Optimization
B26: Backtest: violations in period 2 | C26: =Backtest!C18 -> 3 | D26: Backtest
B27: Backtest: observed violation rate (5% expected) | C27: =Backtest!C20 -> 0.012244898 | D27: Backtest
B28: Backtest: Kupiec p-value | C28: =Backtest!C24 -> 0.0012456625 | D28: Backtest
B30: Sheet guide
B31: Inputs | C31: Parameters you can change (portfolio value, confidence level, crash window, ...).
B32: Prices | C32: Daily closing prices (hardcoded inputs).
B33: Returns | C33: Daily returns, portfolio series, index, drawdown.
B34: Returns_Helper | C34: Series excluding / inside the crash window (support for statistics).
B35: Risk_Metrics | C35: Volatility, VaR, Expected Shortfall, crash effect, drawdown, risk by stock.
B36: Correlation | C36: Correlation matrices: full period, excluding the crash, crash only.
B37: Optimization | C37: Minimum-variance weights, covariance matrix, Solver steps, out-of-sample check.
B38: Backtest | C38: VaR backtest with Kupiec test.
B40: Educational analysis based on two years of historical data. It is not investment advice.

Sheet Inputs
A1: Inputs and assumptions
A2: Blue cells are hardcoded inputs; change them and every sheet recalculates.
B3: Parameter | C3: Value | D3: Comment
B4: Portfolio value (R$) | C4: 1000000 | D4: Hypothetical portfolio used to convert percentages into R$.
B5: Tail probability (1 - confidence level) | C5: 0.05 | D5: 5% = 95% confidence level for VaR and Expected Shortfall.
B6: Crash window start | C6: 43881 | D6: Start of the Covid-19 crash window used in the 'with / without crash' comparison.
B7: Crash window end | C7: 43951 | D7: End of the crash window.
B8: Trading days per year | C8: 252 | D8: Used to annualise daily volatility (x SQRT(252)).
B9: Training period end | C9: 44069 | D9: Last day used to estimate VaR / weights in the out-of-sample and backtest checks.
B10: Backtest window (trading days) | C10: 245 | D10: Length of each period in the backtest (same as the course exercise).
B11: Weight cap in constrained scenario | C11: 0.3 | D11: Maximum weight per stock in the '30% cap' optimisation scenario.
B12: Date excluded as series break (Lojas Americanas) | C12: 44383 | D12: -59.8% in one day while the other stocks moved between -4.1% and +0.5%.
B15: Colour legend
B16: Blue font | C16: Hardcoded input (prices, optimiser weights, parameters)
B17: Black font | C17: Formula calculated in the same sheet
B18: Green font | C18: Formula linking to another sheet
B19: Yellow fill | C19: Key assumption you can change

Sheet Prices
A1: Daily closing prices (R$)
A2: Source: Yahoo Finance Brazil, as provided in the course exercise. Hardcoded inputs.
A3: Date | B3: Arezzo&Co | C3: B3 | D3: Klabin | E3: Localiza | F3: Lojas Americanas | G3: Multiplan | H3: Petrobras | I3: SulAmerica | J3: Vale
A4: 43707 | B4: 49.48 | C4: 14.933333 | D4: 15.06 | E4: 44.799999 | F4: 18.666086 | G4: 25.99 | H4: 25.5 | I4: 44.84446 | J4: 45.57
A5: 43710 | B5: 48.200001 | C5: 14.646666 | D5: 14.97 | E5: 44.666664 | F5: 18.53653 | G5: 26.200001 | H5: 25.299999 | I5: 44.585297 | J5: 46.009998
A6: 43711 | B6: 47.599998 | C6: 14.583333 | D6: 14.8 | E6: 44.342857 | F6: 18.566427 | G6: 26.040001 | H6: 25.6 | I6: 42.715618 | J6: 45.52
A7: 43712 | B7: 48.09 | C7: 14.876666 | D7: 15.1 | E7: 44.933334 | F7: 18.975029 | G7: 26.299999 | H7: 26.26 | I7: 43.317249 | J7: 46.52
A8: 43713 | B8: 48.43 | C8: 15.1 | D8: 14.99 | E8: 45 | F8: 18.915234 | G8: 26.57 | H8: 26.389999 | I8: 43.502365 | J8: 46.52
A9: 43714 | B9: 47.990002 | C9: 15.3 | D9: 15 | E9: 44.599998 | F9: 18.68602 | G9: 26.299999 | H9: 26.52 | I9: 42.613808 | J9: 46.450001
A10: 43717 | B10: 47.93 | C10: 14.606666 | D10: 15.2 | E10: 43.352379 | F10: 18.387041 | G10: 25.540001 | H10: 26.93 | I10: 41.419804 | J10: 47.889999
A11: 43718 | B11: 47.810001 | C11: 14.633333 | D11: 15.09 | E11: 42.75238 | F11: 17.799055 | G11: 26.07 | H11: 27.1 | I11: 41.651199 | J11: 48.240002
A12: 43719 | B12: 49.459999 | C12: 14.843333 | D12: 15.22 | E12: 43.476189 | F12: 18.725882 | G12: 27.049999 | H12: 26.870001 | I12: 42.511993 | J12: 47.950001
A13: 43720 | B13: 48.700001 | C13: 14.826666 | D13: 15.28 | E13: 43.285713 | F13: 18.795643 | G13: 26.860001 | H13: 27.059999 | I13: 42.391666 | J13: 49.689999
A14: 43721 | B14: 48.099998 | C14: 14.333333 | D14: 15.31 | E14: 41.904762 | F14: 18.377075 | G14: 25.950001 | H14: 26.879999 | I14: 42.576782 | J14: 49.790001
A15: 43724 | B15: 48.209999 | C15: 14.356666 | D15: 15.32 | E15: 42.133331 | F15: 18.616257 | G15: 26.33 | H15: 28.059999 | I15: 42.549015 | J15: 48.59
... A495: 44435 | B495: 92.389999 | C495: 13.94 | D495: 26.719999 | E495: 58.299999 | F495: 5.95 | G495: 21.48 | H495: 28.49 | I495: 29.58 | J495: 100.69

Sheet Returns
A1: Daily returns and portfolio series
A2: Return = price today / price yesterday - 1. Portfolio columns use the weight rows of the 'Optimization' sheet.
A3: Date | B3: Arezzo&Co | C3: B3 | D3: Klabin | E3: Localiza | F3: Lojas Americanas | G3: Multiplan | H3: Petrobras | I3: SulAmerica | J3: Vale | K3: Portfolio: equal weights | L3: Portfolio: min. variance | M3: Portfolio: min. variance, 30% cap | N3: Portfolio: min. variance (trained to training end) | O3: In crash window (1 = yes) | P3: Portfolio index (equal weights, base 100) | Q3: Running peak | R3: Drawdown | S3: Lojas Americanas excl. series-break day | T3: Peak recovered (1 = yes) | U3: Equal-weight portfolio excl. series-break day
A4: =Prices!A5 -> 43710 | B4: =Prices!B5/Prices!B4-1 -> -0.025869018 | C4: =Prices!C5/Prices!C4-1 -> -0.019196451 | D4: =Prices!D5/Prices!D4-1 -> -0.0059760956 | E4: =Prices!E5/Prices!E4-1 -> -0.0029762277 | F4: =Prices!F5/Prices!F4-1 -> -0.0069407159 | G4: =Prices!G5/Prices!G4-1 -> 0.0080800693 | H4: =Prices!H5/Prices!H4-1 -> -0.0078431765 | I4: =Prices!I5/Prices!I4-1 -> -0.0057791531 | J4: =Prices!J5/Prices!J4-1 -> 0.0096554312 | K4: =SUMPRODUCT(B4:J4,Optimization!$C$7:$K$7) -> -0.0063161486 | L4: =SUMPRODUCT(B4:J4,Optimization!$C$8:$K$8) -> -0.0082165474 | M4: =SUMPRODUCT(B4:J4,Optimization!$C$9:$K$9) -> -0.0079664575 | N4: =SUMPRODUCT(B4:J4,Optimization!$C$10:$K$10) -> -0.0090282612 | O4: =IF(AND(A4>=Inputs!$C$6,A4<=Inputs!$C$7),1,0) -> 0 | P4: =100*(1+K4) -> 99.368385 | Q4: =MAX(100,P4) -> 100 | R4: =P4/Q4-1 -> -0.0063161486 | S4: =IF(A4=Inputs!$C$12,"",F4) -> -0.0069407159 | T4: =0 -> 0 | U4: =IF(A4=Inputs!$C$12,"",K4) -> -0.0063161486
A5: =Prices!A6 -> 43711 | B5: =Prices!B6/Prices!B5-1 -> -0.012448195 | C5: =Prices!C6/Prices!C5-1 -> -0.0043240557 | D5: =Prices!D6/Prices!D5-1 -> -0.011356045 | E5: =Prices!E6/Prices!E5-1 -> -0.0072494109 | F5: =Prices!F6/Prices!F5-1 -> 0.0016128693 | G5: =Prices!G6/Prices!G5-1 -> -0.00610687 | H5: =Prices!H6/Prices!H5-1 -> 0.011857748 | I5: =Prices!I6/Prices!I5-1 -> -0.041934878 | J5: =Prices!J6/Prices!J5-1 -> -0.010649816 | K5: =SUMPRODUCT(B5:J5,Optimization!$C$7:$K$7) -> -0.008955406 | L5: =SUMPRODUCT(B5:J5,Optimization!$C$8:$K$8) -> -0.013521523 | M5: =SUMPRODUCT(B5:J5,Optimization!$C$9:$K$9) -> -0.014534048 | N5: =SUMPRODUCT(B5:J5,Optimization!$C$10:$K$10) -> -0.011558772 | O5: =IF(AND(A5>=Inputs!$C$6,A5<=Inputs!$C$7),1,0) -> 0 | P5: =P4*(1+K5) -> 98.478501 | Q5: =MAX(Q4,P5) -> 100 | R5: =P5/Q5-1 -> -0.015214991 | S5: =IF(A5=Inputs!$C$12,"",F5) -> 0.0016128693 | T5: =IF(AND(A5>Risk_Metrics!$C$28,P5>=Risk_Metrics!$C$30),1,0) -> 0 | U5: =IF(A5=Inputs!$C$12,"",K5) -> -0.008955406
A6: =Prices!A7 -> 43712 | B6: =Prices!B7/Prices!B6-1 -> 0.01029416 | C6: =Prices!C7/Prices!C6-1 -> 0.020114263 | D6: =Prices!D7/Prices!D6-1 -> 0.02027027 | E6: =Prices!E7/Prices!E6-1 -> 0.01331617 | F6: =Prices!F7/Prices!F6-1 -> 0.022007573 | G6: =Prices!G7/Prices!G6-1 -> 0.0099845618 | H6: =Prices!H7/Prices!H6-1 -> 0.02578125 | I6: =Prices!I7/Prices!I6-1 -> 0.014084567 | J6: =Prices!J7/Prices!J6-1 -> 0.021968366 | K6: =SUMPRODUCT(B6:J6,Optimization!$C$7:$K$7) -> 0.017535687 | L6: =SUMPRODUCT(B6:J6,Optimization!$C$8:$K$8) -> 0.01835297 | M6: =SUMPRODUCT(B6:J6,Optimization!$C$9:$K$9) -> 0.017953357 | N6: =SUMPRODUCT(B6:J6,Optimization!$C$10:$K$10) -> 0.018506215 | O6: =IF(AND(A6>=Inputs!$C$6,A6<=Inputs!$C$7),1,0) -> 0 | P6: =P5*(1+K6) -> 100.20539 | Q6: =MAX(Q5,P6) -> 100.20539 | R6: =P6/Q6-1 -> 0 | S6: =IF(A6=Inputs!$C$12,"",F6) -> 0.022007573 | T6: =IF(AND(A6>Risk_Metrics!$C$28,P6>=Risk_Metrics!$C$30),1,0) -> 0 | U6: =IF(A6=Inputs!$C$12,"",K6) -> 0.017535687
A7: =Prices!A8 -> 43713 | B7: =Prices!B8/Prices!B7-1 -> 0.0070700769 | C7: =Prices!C8/Prices!C7-1 -> 0.015012369 | D7: =Prices!D8/Prices!D7-1 -> -0.0072847682 | E7: =Prices!E8/Prices!E7-1 -> 0.0014836647 | F7: =Prices!F8/Prices!F7-1 -> -0.0031512468 | G7: =Prices!G8/Prices!G7-1 -> 0.010266198 | H7: =Prices!H8/Prices!H7-1 -> 0.004950457 | I7: =Prices!I8/Prices!I7-1 -> 0.0042734939 | J7: =Prices!J8/Prices!J7-1 -> 0 | K7: =SUMPRODUCT(B7:J7,Optimization!$C$7:$K$7) -> 0.0036244716 | L7: =SUMPRODUCT(B7:J7,Optimization!$C$8:$K$8) -> 0.00021901892 | M7: =SUMPRODUCT(B7:J7,Optimization!$C$9:$K$9) -> 0.0019051953 | N7: =SUMPRODUCT(B7:J7,Optimization!$C$10:$K$10) -> -0.00017926269 | O7: =IF(AND(A7>=Inputs!$C$6,A7<=Inputs!$C$7),1,0) -> 0 | P7: =P6*(1+K7) -> 100.56858 | Q7: =MAX(Q6,P7) -> 100.56858 | R7: =P7/Q7-1 -> 0 | S7: =IF(A7=Inputs!$C$12,"",F7) -> -0.0031512468 | T7: =IF(AND(A7>Risk_Metrics!$C$28,P7>=Risk_Metrics!$C$30),1,0) -> 0 | U7: =IF(A7=Inputs!$C$12,"",K7) -> 0.0036244716
A8: =Prices!A9 -> 43714 | B8: =Prices!B9/Prices!B8-1 -> -0.0090852364 | C8: =Prices!C9/Prices!C8-1 -> 0.013245033 | D8: =Prices!D9/Prices!D8-1 -> 0.00066711141 | E8: =Prices!E9/Prices!E8-1 -> -0.0088889333 | F8: =Prices!F9/Prices!F8-1 -> -0.012117957 | G8: =Prices!G9/Prices!G8-1 -> -0.010161874 | H8: =Prices!H9/Prices!H8-1 -> 0.0049261465 | I8: =Prices!I9/Prices!I8-1 -> -0.020425487 | J8: =Prices!J9/Prices!J8-1 -> -0.0015047077 | K8: =SUMPRODUCT(B8:J8,Optimization!$C$7:$K$7) -> -0.0048162117 | L8: =SUMPRODUCT(B8:J8,Optimization!$C$8:$K$8) -> -0.0016717308 | M8: =SUMPRODUCT(B8:J8,Optimization!$C$9:$K$9) -> -0.0026947249 | N8: =SUMPRODUCT(B8:J8,Optimization!$C$10:$K$10) -> -0.00039871718 | O8: =IF(AND(A8>=Inputs!$C$6,A8<=Inputs!$C$7),1,0) -> 0 | P8: =P7*(1+K8) -> 100.08422 | Q8: =MAX(Q7,P8) -> 100.56858 | R8: =P8/Q8-1 -> -0.0048162117 | S8: =IF(A8=Inputs!$C$12,"",F8) -> -0.012117957 | T8: =IF(AND(A8>Risk_Metrics!$C$28,P8>=Risk_Metrics!$C$30),1,0) -> 0 | U8: =IF(A8=Inputs!$C$12,"",K8) -> -0.0048162117
A9: =Prices!A10 -> 43717 | B9: =Prices!B10/Prices!B9-1 -> -0.0012503021 | C9: =Prices!C10/Prices!C9-1 -> -0.045315948 | D9: =Prices!D10/Prices!D9-1 -> 0.013333333 | E9: =Prices!E10/Prices!E9-1 -> -0.027973521 | F9: =Prices!F10/Prices!F9-1 -> -0.016000143 | G9: =Prices!G10/Prices!G9-1 -> -0.028897263 | H9: =Prices!H10/Prices!H9-1 -> 0.01546003 | I9: =Prices!I10/Prices!I9-1 -> -0.028019181 | J9: =Prices!J10/Prices!J9-1 -> 0.031001033 | K9: =SUMPRODUCT(B9:J9,Optimization!$C$7:$K$7) -> -0.0097402181 | L9: =SUMPRODUCT(B9:J9,Optimization!$C$8:$K$8) -> 0.002234215 | M9: =SUMPRODUCT(B9:J9,Optimization!$C$9:$K$9) -> 0.00036885484 | N9: =SUMPRODUCT(B9:J9,Optimization!$C$10:$K$10) -> 0.0037938368 | O9: =IF(AND(A9>=Inputs!$C$6,A9<=Inputs!$C$7),1,0) -> 0 | P9: =P8*(1+K9) -> 99.109379 | Q9: =MAX(Q8,P9) -> 100.56858 | R9: =P9/Q9-1 -> -0.014509519 | S9: =IF(A9=Inputs!$C$12,"",F9) -> -0.016000143 | T9: =IF(AND(A9>Risk_Metrics!$C$28,P9>=Risk_Metrics!$C$30),1,0) -> 0 | U9: =IF(A9=Inputs!$C$12,"",K9) -> -0.0097402181
A10: =Prices!A11 -> 43718 | B10: =Prices!B11/Prices!B10-1 -> -0.0025036303 | C10: =Prices!C11/Prices!C10-1 -> 0.0018256733 | D10: =Prices!D11/Prices!D10-1 -> -0.0072368421 | E10: =Prices!E11/Prices!E10-1 -> -0.013840048 | F10: =Prices!F11/Prices!F10-1 -> -0.031978283 | G10: =Prices!G11/Prices!G10-1 -> 0.020751722 | H10: =Prices!H11/Prices!H10-1 -> 0.0063126625 | I10: =Prices!I11/Prices!I10-1 -> 0.0055865788 | J10: =Prices!J11/Prices!J10-1 -> 0.0073084779 | K10: =SUMPRODUCT(B10:J10,Optimization!$C$7:$K$7) -> -0.0015304099 | L10: =SUMPRODUCT(B10:J10,Optimization!$C$8:$K$8) -> -0.0016412388 | M10: =SUMPRODUCT(B10:J10,Optimization!$C$9:$K$9) -> 3.0491917e-05 | N10: =SUMPRODUCT(B10:J10,Optimization!$C$10:$K$10) -> -0.0025530711 | O10: =IF(AND(A10>=Inputs!$C$6,A10<=Inputs!$C$7),1,0) -> 0 | P10: =P9*(1+K10) -> 98.957701 | Q10: =MAX(Q9,P10) -> 100.56858 | R10: =P10/Q10-1 -> -0.016017723 | S10: =IF(A10=Inputs!$C$12,"",F10) -> -0.031978283 | T10: =IF(AND(A10>Risk_Metrics!$C$28,P10>=Risk_Metrics!$C$30),1,0) -> 0 | U10: =IF(A10=Inputs!$C$12,"",K10) -> -0.0015304099
A11: =Prices!A12 -> 43719 | B11: =Prices!B12/Prices!B11-1 -> 0.034511566 | C11: =Prices!C12/Prices!C11-1 -> 0.014350798 | D11: =Prices!D12/Prices!D11-1 -> 0.0086149768 | E11: =Prices!E12/Prices!E11-1 -> 0.016930262 | F11: =Prices!F12/Prices!F11-1 -> 0.052071697 | G11: =Prices!G12/Prices!G11-1 -> 0.037591063 | H11: =Prices!H12/Prices!H11-1 -> -0.008487048 | I11: =Prices!I12/Prices!I11-1 -> 0.020666728 | J11: =Prices!J12/Prices!J11-1 -> -0.0060116291 | K11: =SUMPRODUCT(B11:J11,Optimization!$C$7:$K$7) -> 0.018915379 | L11: =SUMPRODUCT(B11:J11,Optimization!$C$8:$K$8) -> 0.012201186 | M11: =SUMPRODUCT(B11:J11,Optimization!$C$9:$K$9) -> 0.012591773 | N11: =SUMPRODUCT(B11:J11,Optimization!$C$10:$K$10) -> 0.012284029 | O11: =IF(AND(A11>=Inputs!$C$6,A11<=Inputs!$C$7),1,0) -> 0 | P11: =P10*(1+K11) -> 100.82952 | Q11: =MAX(Q10,P11) -> 100.82952 | R11: =P11/Q11-1 -> 0 | S11: =IF(A11=Inputs!$C$12,"",F11) -> 0.052071697 | T11: =IF(AND(A11>Risk_Metrics!$C$28,P11>=Risk_Metrics!$C$30),1,0) -> 0 | U11: =IF(A11=Inputs!$C$12,"",K11) -> 0.018915379
A12: =Prices!A13 -> 43720 | B12: =Prices!B13/Prices!B12-1 -> -0.015365912 | C12: =Prices!C13/Prices!C12-1 -> -0.001122861 | D12: =Prices!D13/Prices!D12-1 -> 0.0039421813 | E12: =Prices!E13/Prices!E12-1 -> -0.0043811568 | F12: =Prices!F13/Prices!F12-1 -> 0.0037253786 | G12: =Prices!G13/Prices!G12-1 -> -0.0070239559 | H12: =Prices!H13/Prices!H12-1 -> 0.0070710083 | I12: =Prices!I13/Prices!I12-1 -> -0.0028304248 | J12: =Prices!J13/Prices!J12-1 -> 0.036287757 | K12: =SUMPRODUCT(B12:J12,Optimization!$C$7:$K$7) -> 0.0022557794 | L12: =SUMPRODUCT(B12:J12,Optimization!$C$8:$K$8) -> 0.0049276388 | M12: =SUMPRODUCT(B12:J12,Optimization!$C$9:$K$9) -> 0.0061467031 | N12: =SUMPRODUCT(B12:J12,Optimization!$C$10:$K$10) -> 0.0043301821 | O12: =IF(AND(A12>=Inputs!$C$6,A12<=Inputs!$C$7),1,0) -> 0 | P12: =P11*(1+K12) -> 101.05697 | Q12: =MAX(Q11,P12) -> 101.05697 | R12: =P12/Q12-1 -> 0 | S12: =IF(A12=Inputs!$C$12,"",F12) -> 0.0037253786 | T12: =IF(AND(A12>Risk_Metrics!$C$28,P12>=Risk_Metrics!$C$30),1,0) -> 0 | U12: =IF(A12=Inputs!$C$12,"",K12) -> 0.0022557794
A13: =Prices!A14 -> 43721 | B13: =Prices!B14/Prices!B13-1 -> -0.01232039 | C13: =Prices!C14/Prices!C13-1 -> -0.03327336 | D13: =Prices!D14/Prices!D13-1 -> 0.0019633508 | E13: =Prices!E14/Prices!E13-1 -> -0.031903159 | F13: =Prices!F14/Prices!F13-1 -> -0.022269416 | G13: =Prices!G14/Prices!G13-1 -> -0.033879373 | H13: =Prices!H14/Prices!H13-1 -> -0.0066518849 | I13: =Prices!I14/Prices!I13-1 -> 0.0043668017 | J13: =Prices!J14/Prices!J13-1 -> 0.0020125176 | K13: =SUMPRODUCT(B13:J13,Optimization!$C$7:$K$7) -> -0.014661657 | L13: =SUMPRODUCT(B13:J13,Optimization!$C$8:$K$8) -> -0.0046205363 | M13: =SUMPRODUCT(B13:J13,Optimization!$C$9:$K$9) -> -0.0055468549 | N13: =SUMPRODUCT(B13:J13,Optimization!$C$10:$K$10) -> -0.0053401561 | O13: =IF(AND(A13>=Inputs!$C$6,A13<=Inputs!$C$7),1,0) -> 0 | P13: =P12*(1+K13) -> 99.57531 | Q13: =MAX(Q12,P13) -> 101.05697 | R13: =P13/Q13-1 -> -0.014661657 | S13: =IF(A13=Inputs!$C$12,"",F13) -> -0.022269416 | T13: =IF(AND(A13>Risk_Metrics!$C$28,P13>=Risk_Metrics!$C$30),1,0) -> 0 | U13: =IF(A13=Inputs!$C$12,"",K13) -> -0.014661657
A14: =Prices!A15 -> 43724 | B14: =Prices!B15/Prices!B14-1 -> 0.0022869232 | C14: =Prices!C15/Prices!C14-1 -> 0.0016278838 | D14: =Prices!D15/Prices!D14-1 -> 0.00065316786 | E14: =Prices!E15/Prices!E14-1 -> 0.0054544875 | F14: =Prices!F15/Prices!F14-1 -> 0.013015238 | G14: =Prices!G15/Prices!G14-1 -> 0.014643506 | H14: =Prices!H15/Prices!H14-1 -> 0.043898811 | I14: =Prices!I15/Prices!I14-1 -> -0.00065216296 | J14: =Prices!J15/Prices!J14-1 -> -0.024101245 | K14: =SUMPRODUCT(B14:J14,Optimization!$C$7:$K$7) -> 0.0063140677 | L14: =SUMPRODUCT(B14:J14,Optimization!$C$8:$K$8) -> -0.0031833352 | M14: =SUMPRODUCT(B14:J14,Optimization!$C$9:$K$9) -> -0.0047531746 | N14: =SUMPRODUCT(B14:J14,Optimization!$C$10:$K$10) -> -0.002609742 | O14: =IF(AND(A14>=Inputs!$C$6,A14<=Inputs!$C$7),1,0) -> 0 | P14: =P13*(1+K14) -> 100.20404 | Q14: =MAX(Q13,P14) -> 101.05697 | R14: =P14/Q14-1 -> -0.0084401641 | S14: =IF(A14=Inputs!$C$12,"",F14) -> 0.013015238 | T14: =IF(AND(A14>Risk_Metrics!$C$28,P14>=Risk_Metrics!$C$30),1,0) -> 0 | U14: =IF(A14=Inputs!$C$12,"",K14) -> 0.0063140677
A15: =Prices!A16 -> 43725 | B15: =Prices!B16/Prices!B15-1 -> 0.018046111 | C15: =Prices!C16/Prices!C15-1 -> 0.024378919 | D15: =Prices!D16/Prices!D15-1 -> 0.0045691906 | E15: =Prices!E16/Prices!E15-1 -> 0.0058770573 | F15: =Prices!F16/Prices!F15-1 -> 0.025160643 | G15: =Prices!G16/Prices!G15-1 -> 0.023927041 | H15: =Prices!H16/Prices!H15-1 -> -0.013185959 | I15: =Prices!I16/Prices!I15-1 -> 0.0069611012 | J15: =Prices!J16/Prices!J15-1 -> 0.0063799547 | K15: =SUMPRODUCT(B15:J15,Optimization!$C$7:$K$7) -> 0.011346007 | L15: =SUMPRODUCT(B15:J15,Optimization!$C$8:$K$8) -> 0.0097995044 | M15: =SUMPRODUCT(B15:J15,Optimization!$C$9:$K$9) -> 0.010742712 | N15: =SUMPRODUCT(B15:J15,Optimization!$C$10:$K$10) -> 0.010046314 | O15: =IF(AND(A15>=Inputs!$C$6,A15<=Inputs!$C$7),1,0) -> 0 | P15: =P14*(1+K15) -> 101.34095 | Q15: =MAX(Q14,P15) -> 101.34095 | R15: =P15/Q15-1 -> 0 | S15: =IF(A15=Inputs!$C$12,"",F15) -> 0.025160643 | T15: =IF(AND(A15>Risk_Metrics!$C$28,P15>=Risk_Metrics!$C$30),1,0) -> 0 | U15: =IF(A15=Inputs!$C$12,"",K15) -> 0.011346007
A16: =Prices!A17 -> 43726 | B16: =Prices!B17/Prices!B16-1 -> 0.0044824163 | C16: =Prices!C17/Prices!C16-1 -> 0.01813239 | D16: =Prices!D17/Prices!D16-1 -> 0.0090968161 | E16: =Prices!E17/Prices!E16-1 -> 0.014157351 | F16: =Prices!F17/Prices!F16-1 -> 0 | G16: =Prices!G17/Prices!G16-1 -> 0.0092729974 | H16: =Prices!H17/Prices!H16-1 -> -0.016973708 | I16: =Prices!I17/Prices!I16-1 -> -0.0030244926 | J16: =Prices!J17/Prices!J16-1 -> -0.010224948 | K16: =SUMPRODUCT(B16:J16,Optimization!$C$7:$K$7) -> 0.0027687579 | L16: =SUMPRODUCT(B16:J16,Optimization!$C$8:$K$8) -> 0.0051568348 | M16: =SUMPRODUCT(B16:J16,Optimization!$C$9:$K$9) -> 0.0034544677 | N16: =SUMPRODUCT(B16:J16,Optimization!$C$10:$K$10) -> 0.0062506671 | O16: =IF(AND(A16>=Inputs!$C$6,A16<=Inputs!$C$7),1,0) -> 0 | P16: =P15*(1+K16) -> 101.62154 | Q16: =MAX(Q15,P16) -> 101.62154 | R16: =P16/Q16-1 -> 0 | S16: =IF(A16=Inputs!$C$12,"",F16) -> 0 | T16: =IF(AND(A16>Risk_Metrics!$C$28,P16>=Risk_Metrics!$C$30),1,0) -> 0 | U16: =IF(A16=Inputs!$C$12,"",K16) -> 0.0027687579
... A494: =Prices!A495 -> 44435 | B494: =Prices!B495/Prices!B494-1 -> 0.011717028 | C494: =Prices!C495/Prices!C494-1 -> 0.020497804 | D494: =Prices!D495/Prices!D494-1 -> 0.013272582 | E494: =Prices!E495/Prices!E494-1 -> 0.041815583 | F494: =Prices!F495/Prices!F494-1 -> 0 | G494: =Prices!G495/Prices!G494-1 -> 0.019458946 | H494: =Prices!H495/Prices!H494-1 -> 0.036376864 | I494: =Prices!I495/Prices!I494-1 -> 0.010245867 | J494: =Prices!J495/Prices!J494-1 -> 0.025043255 | K494: =SUMPRODUCT(B494:J494,Optimization!$C$7:$K$7) -> 0.019825326 | L494: =SUMPRODUCT(B494:J494,Optimization!$C$8:$K$8) -> 0.015614886 | M494: =SUMPRODUCT(B494:J494,Optimization!$C$9:$K$9) -> 0.016317574 | N494: =SUMPRODUCT(B494:J494,Optimization!$C$10:$K$10) -> 0.015616306 | O494: =IF(AND(A494>=Inputs!$C$6,A494<=Inputs!$C$7),1,0) -> 0 | P494: =P493*(1+K494) -> 122.55224 | Q494: =MAX(Q493,P494) -> 149.3157 | R494: =P494/Q494-1 -> -0.17924079 | S494: =IF(A494=Inputs!$C$12,"",F494) -> 0 | T494: =IF(AND(A494>Risk_Metrics!$C$28,P494>=Risk_Metrics!$C$30),1,0) -> 0 | U494: =IF(A494=Inputs!$C$12,"",K494) -> 0.019825326

Sheet Returns_Helper
A1: Helper series for the 'excluding crash' and 'crash only' calculations
A2: Cells are blank (text) when the day is outside / inside the crash window, so statistics functions ignore them.
A3: Date | B3: Arezzo&Co (excl. crash) | C3: B3 (excl. crash) | D3: Klabin (excl. crash) | E3: Localiza (excl. crash) | F3: Lojas Americanas (excl. crash) | G3: Multiplan (excl. crash) | H3: Petrobras (excl. crash) | I3: SulAmerica (excl. crash) | J3: Vale (excl. crash) | K3: Arezzo&Co (crash only) | L3: B3 (crash only) | M3: Klabin (crash only) | N3: Localiza (crash only) | O3: Lojas Americanas (crash only) | P3: Multiplan (crash only) | Q3: Petrobras (crash only) | R3: SulAmerica (crash only) | S3: Vale (crash only) | T3: Equal-weight portfolio (excl. crash)
A4: =Returns!A4 -> 43710 | B4: =IF(Returns!$O4=1,"",Returns!B4) -> -0.025869018 | C4: =IF(Returns!$O4=1,"",Returns!C4) -> -0.019196451 | D4: =IF(Returns!$O4=1,"",Returns!D4) -> -0.0059760956 | E4: =IF(Returns!$O4=1,"",Returns!E4) -> -0.0029762277 | F4: =IF(Returns!$O4=1,"",Returns!F4) -> -0.0069407159 | G4: =IF(Returns!$O4=1,"",Returns!G4) -> 0.0080800693 | H4: =IF(Returns!$O4=1,"",Returns!H4) -> -0.0078431765 | I4: =IF(Returns!$O4=1,"",Returns!I4) -> -0.0057791531 | J4: =IF(Returns!$O4=1,"",Returns!J4) -> 0.0096554312 | K4: =IF(Returns!$O4=1,Returns!B4,"") | L4: =IF(Returns!$O4=1,Returns!C4,"") | M4: =IF(Returns!$O4=1,Returns!D4,"") | N4: =IF(Returns!$O4=1,Returns!E4,"") | O4: =IF(Returns!$O4=1,Returns!F4,"") | P4: =IF(Returns!$O4=1,Returns!G4,"") | Q4: =IF(Returns!$O4=1,Returns!H4,"") | R4: =IF(Returns!$O4=1,Returns!I4,"") | S4: =IF(Returns!$O4=1,Returns!J4,"") | T4: =IF(Returns!$O4=1,"",Returns!K4) -> -0.0063161486
A5: =Returns!A5 -> 43711 | B5: =IF(Returns!$O5=1,"",Returns!B5) -> -0.012448195 | C5: =IF(Returns!$O5=1,"",Returns!C5) -> -0.0043240557 | D5: =IF(Returns!$O5=1,"",Returns!D5) -> -0.011356045 | E5: =IF(Returns!$O5=1,"",Returns!E5) -> -0.0072494109 | F5: =IF(Returns!$O5=1,"",Returns!F5) -> 0.0016128693 | G5: =IF(Returns!$O5=1,"",Returns!G5) -> -0.00610687 | H5: =IF(Returns!$O5=1,"",Returns!H5) -> 0.011857748 | I5: =IF(Returns!$O5=1,"",Returns!I5) -> -0.041934878 | J5: =IF(Returns!$O5=1,"",Returns!J5) -> -0.010649816 | K5: =IF(Returns!$O5=1,Returns!B5,"") | L5: =IF(Returns!$O5=1,Returns!C5,"") | M5: =IF(Returns!$O5=1,Returns!D5,"") | N5: =IF(Returns!$O5=1,Returns!E5,"") | O5: =IF(Returns!$O5=1,Returns!F5,"") | P5: =IF(Returns!$O5=1,Returns!G5,"") | Q5: =IF(Returns!$O5=1,Returns!H5,"") | R5: =IF(Returns!$O5=1,Returns!I5,"") | S5: =IF(Returns!$O5=1,Returns!J5,"") | T5: =IF(Returns!$O5=1,"",Returns!K5) -> -0.008955406
A6: =Returns!A6 -> 43712 | B6: =IF(Returns!$O6=1,"",Returns!B6) -> 0.01029416 | C6: =IF(Returns!$O6=1,"",Returns!C6) -> 0.020114263 | D6: =IF(Returns!$O6=1,"",Returns!D6) -> 0.02027027 | E6: =IF(Returns!$O6=1,"",Returns!E6) -> 0.01331617 | F6: =IF(Returns!$O6=1,"",Returns!F6) -> 0.022007573 | G6: =IF(Returns!$O6=1,"",Returns!G6) -> 0.0099845618 | H6: =IF(Returns!$O6=1,"",Returns!H6) -> 0.02578125 | I6: =IF(Returns!$O6=1,"",Returns!I6) -> 0.014084567 | J6: =IF(Returns!$O6=1,"",Returns!J6) -> 0.021968366 | K6: =IF(Returns!$O6=1,Returns!B6,"") | L6: =IF(Returns!$O6=1,Returns!C6,"") | M6: =IF(Returns!$O6=1,Returns!D6,"") | N6: =IF(Returns!$O6=1,Returns!E6,"") | O6: =IF(Returns!$O6=1,Returns!F6,"") | P6: =IF(Returns!$O6=1,Returns!G6,"") | Q6: =IF(Returns!$O6=1,Returns!H6,"") | R6: =IF(Returns!$O6=1,Returns!I6,"") | S6: =IF(Returns!$O6=1,Returns!J6,"") | T6: =IF(Returns!$O6=1,"",Returns!K6) -> 0.017535687
A7: =Returns!A7 -> 43713 | B7: =IF(Returns!$O7=1,"",Returns!B7) -> 0.0070700769 | C7: =IF(Returns!$O7=1,"",Returns!C7) -> 0.015012369 | D7: =IF(Returns!$O7=1,"",Returns!D7) -> -0.0072847682 | E7: =IF(Returns!$O7=1,"",Returns!E7) -> 0.0014836647 | F7: =IF(Returns!$O7=1,"",Returns!F7) -> -0.0031512468 | G7: =IF(Returns!$O7=1,"",Returns!G7) -> 0.010266198 | H7: =IF(Returns!$O7=1,"",Returns!H7) -> 0.004950457 | I7: =IF(Returns!$O7=1,"",Returns!I7) -> 0.0042734939 | J7: =IF(Returns!$O7=1,"",Returns!J7) -> 0 | K7: =IF(Returns!$O7=1,Returns!B7,"") | L7: =IF(Returns!$O7=1,Returns!C7,"") | M7: =IF(Returns!$O7=1,Returns!D7,"") | N7: =IF(Returns!$O7=1,Returns!E7,"") | O7: =IF(Returns!$O7=1,Returns!F7,"") | P7: =IF(Returns!$O7=1,Returns!G7,"") | Q7: =IF(Returns!$O7=1,Returns!H7,"") | R7: =IF(Returns!$O7=1,Returns!I7,"") | S7: =IF(Returns!$O7=1,Returns!J7,"") | T7: =IF(Returns!$O7=1,"",Returns!K7) -> 0.0036244716
A8: =Returns!A8 -> 43714 | B8: =IF(Returns!$O8=1,"",Returns!B8) -> -0.0090852364 | C8: =IF(Returns!$O8=1,"",Returns!C8) -> 0.013245033 | D8: =IF(Returns!$O8=1,"",Returns!D8) -> 0.00066711141 | E8: =IF(Returns!$O8=1,"",Returns!E8) -> -0.0088889333 | F8: =IF(Returns!$O8=1,"",Returns!F8) -> -0.012117957 | G8: =IF(Returns!$O8=1,"",Returns!G8) -> -0.010161874 | H8: =IF(Returns!$O8=1,"",Returns!H8) -> 0.0049261465 | I8: =IF(Returns!$O8=1,"",Returns!I8) -> -0.020425487 | J8: =IF(Returns!$O8=1,"",Returns!J8) -> -0.0015047077 | K8: =IF(Returns!$O8=1,Returns!B8,"") | L8: =IF(Returns!$O8=1,Returns!C8,"") | M8: =IF(Returns!$O8=1,Returns!D8,"") | N8: =IF(Returns!$O8=1,Returns!E8,"") | O8: =IF(Returns!$O8=1,Returns!F8,"") | P8: =IF(Returns!$O8=1,Returns!G8,"") | Q8: =IF(Returns!$O8=1,Returns!H8,"") | R8: =IF(Returns!$O8=1,Returns!I8,"") | S8: =IF(Returns!$O8=1,Returns!J8,"") | T8: =IF(Returns!$O8=1,"",Returns!K8) -> -0.0048162117
A9: =Returns!A9 -> 43717 | B9: =IF(Returns!$O9=1,"",Returns!B9) -> -0.0012503021 | C9: =IF(Returns!$O9=1,"",Returns!C9) -> -0.045315948 | D9: =IF(Returns!$O9=1,"",Returns!D9) -> 0.013333333 | E9: =IF(Returns!$O9=1,"",Returns!E9) -> -0.027973521 | F9: =IF(Returns!$O9=1,"",Returns!F9) -> -0.016000143 | G9: =IF(Returns!$O9=1,"",Returns!G9) -> -0.028897263 | H9: =IF(Returns!$O9=1,"",Returns!H9) -> 0.01546003 | I9: =IF(Returns!$O9=1,"",Returns!I9) -> -0.028019181 | J9: =IF(Returns!$O9=1,"",Returns!J9) -> 0.031001033 | K9: =IF(Returns!$O9=1,Returns!B9,"") | L9: =IF(Returns!$O9=1,Returns!C9,"") | M9: =IF(Returns!$O9=1,Returns!D9,"") | N9: =IF(Returns!$O9=1,Returns!E9,"") | O9: =IF(Returns!$O9=1,Returns!F9,"") | P9: =IF(Returns!$O9=1,Returns!G9,"") | Q9: =IF(Returns!$O9=1,Returns!H9,"") | R9: =IF(Returns!$O9=1,Returns!I9,"") | S9: =IF(Returns!$O9=1,Returns!J9,"") | T9: =IF(Returns!$O9=1,"",Returns!K9) -> -0.0097402181
A10: =Returns!A10 -> 43718 | B10: =IF(Returns!$O10=1,"",Returns!B10) -> -0.0025036303 | C10: =IF(Returns!$O10=1,"",Returns!C10) -> 0.0018256733 | D10: =IF(Returns!$O10=1,"",Returns!D10) -> -0.0072368421 | E10: =IF(Returns!$O10=1,"",Returns!E10) -> -0.013840048 | F10: =IF(Returns!$O10=1,"",Returns!F10) -> -0.031978283 | G10: =IF(Returns!$O10=1,"",Returns!G10) -> 0.020751722 | H10: =IF(Returns!$O10=1,"",Returns!H10) -> 0.0063126625 | I10: =IF(Returns!$O10=1,"",Returns!I10) -> 0.0055865788 | J10: =IF(Returns!$O10=1,"",Returns!J10) -> 0.0073084779 | K10: =IF(Returns!$O10=1,Returns!B10,"") | L10: =IF(Returns!$O10=1,Returns!C10,"") | M10: =IF(Returns!$O10=1,Returns!D10,"") | N10: =IF(Returns!$O10=1,Returns!E10,"") | O10: =IF(Returns!$O10=1,Returns!F10,"") | P10: =IF(Returns!$O10=1,Returns!G10,"") | Q10: =IF(Returns!$O10=1,Returns!H10,"") | R10: =IF(Returns!$O10=1,Returns!I10,"") | S10: =IF(Returns!$O10=1,Returns!J10,"") | T10: =IF(Returns!$O10=1,"",Returns!K10) -> -0.0015304099
A11: =Returns!A11 -> 43719 | B11: =IF(Returns!$O11=1,"",Returns!B11) -> 0.034511566 | C11: =IF(Returns!$O11=1,"",Returns!C11) -> 0.014350798 | D11: =IF(Returns!$O11=1,"",Returns!D11) -> 0.0086149768 | E11: =IF(Returns!$O11=1,"",Returns!E11) -> 0.016930262 | F11: =IF(Returns!$O11=1,"",Returns!F11) -> 0.052071697 | G11: =IF(Returns!$O11=1,"",Returns!G11) -> 0.037591063 | H11: =IF(Returns!$O11=1,"",Returns!H11) -> -0.008487048 | I11: =IF(Returns!$O11=1,"",Returns!I11) -> 0.020666728 | J11: =IF(Returns!$O11=1,"",Returns!J11) -> -0.0060116291 | K11: =IF(Returns!$O11=1,Returns!B11,"") | L11: =IF(Returns!$O11=1,Returns!C11,"") | M11: =IF(Returns!$O11=1,Returns!D11,"") | N11: =IF(Returns!$O11=1,Returns!E11,"") | O11: =IF(Returns!$O11=1,Returns!F11,"") | P11: =IF(Returns!$O11=1,Returns!G11,"") | Q11: =IF(Returns!$O11=1,Returns!H11,"") | R11: =IF(Returns!$O11=1,Returns!I11,"") | S11: =IF(Returns!$O11=1,Returns!J11,"") | T11: =IF(Returns!$O11=1,"",Returns!K11) -> 0.018915379
A12: =Returns!A12 -> 43720 | B12: =IF(Returns!$O12=1,"",Returns!B12) -> -0.015365912 | C12: =IF(Returns!$O12=1,"",Returns!C12) -> -0.001122861 | D12: =IF(Returns!$O12=1,"",Returns!D12) -> 0.0039421813 | E12: =IF(Returns!$O12=1,"",Returns!E12) -> -0.0043811568 | F12: =IF(Returns!$O12=1,"",Returns!F12) -> 0.0037253786 | G12: =IF(Returns!$O12=1,"",Returns!G12) -> -0.0070239559 | H12: =IF(Returns!$O12=1,"",Returns!H12) -> 0.0070710083 | I12: =IF(Returns!$O12=1,"",Returns!I12) -> -0.0028304248 | J12: =IF(Returns!$O12=1,"",Returns!J12) -> 0.036287757 | K12: =IF(Returns!$O12=1,Returns!B12,"") | L12: =IF(Returns!$O12=1,Returns!C12,"") | M12: =IF(Returns!$O12=1,Returns!D12,"") | N12: =IF(Returns!$O12=1,Returns!E12,"") | O12: =IF(Returns!$O12=1,Returns!F12,"") | P12: =IF(Returns!$O12=1,Returns!G12,"") | Q12: =IF(Returns!$O12=1,Returns!H12,"") | R12: =IF(Returns!$O12=1,Returns!I12,"") | S12: =IF(Returns!$O12=1,Returns!J12,"") | T12: =IF(Returns!$O12=1,"",Returns!K12) -> 0.0022557794
A13: =Returns!A13 -> 43721 | B13: =IF(Returns!$O13=1,"",Returns!B13) -> -0.01232039 | C13: =IF(Returns!$O13=1,"",Returns!C13) -> -0.03327336 | D13: =IF(Returns!$O13=1,"",Returns!D13) -> 0.0019633508 | E13: =IF(Returns!$O13=1,"",Returns!E13) -> -0.031903159 | F13: =IF(Returns!$O13=1,"",Returns!F13) -> -0.022269416 | G13: =IF(Returns!$O13=1,"",Returns!G13) -> -0.033879373 | H13: =IF(Returns!$O13=1,"",Returns!H13) -> -0.0066518849 | I13: =IF(Returns!$O13=1,"",Returns!I13) -> 0.0043668017 | J13: =IF(Returns!$O13=1,"",Returns!J13) -> 0.0020125176 | K13: =IF(Returns!$O13=1,Returns!B13,"") | L13: =IF(Returns!$O13=1,Returns!C13,"") | M13: =IF(Returns!$O13=1,Returns!D13,"") | N13: =IF(Returns!$O13=1,Returns!E13,"") | O13: =IF(Returns!$O13=1,Returns!F13,"") | P13: =IF(Returns!$O13=1,Returns!G13,"") | Q13: =IF(Returns!$O13=1,Returns!H13,"") | R13: =IF(Returns!$O13=1,Returns!I13,"") | S13: =IF(Returns!$O13=1,Returns!J13,"") | T13: =IF(Returns!$O13=1,"",Returns!K13) -> -0.014661657
A14: =Returns!A14 -> 43724 | B14: =IF(Returns!$O14=1,"",Returns!B14) -> 0.0022869232 | C14: =IF(Returns!$O14=1,"",Returns!C14) -> 0.0016278838 | D14: =IF(Returns!$O14=1,"",Returns!D14) -> 0.00065316786 | E14: =IF(Returns!$O14=1,"",Returns!E14) -> 0.0054544875 | F14: =IF(Returns!$O14=1,"",Returns!F14) -> 0.013015238 | G14: =IF(Returns!$O14=1,"",Returns!G14) -> 0.014643506 | H14: =IF(Returns!$O14=1,"",Returns!H14) -> 0.043898811 | I14: =IF(Returns!$O14=1,"",Returns!I14) -> -0.00065216296 | J14: =IF(Returns!$O14=1,"",Returns!J14) -> -0.024101245 | K14: =IF(Returns!$O14=1,Returns!B14,"") | L14: =IF(Returns!$O14=1,Returns!C14,"") | M14: =IF(Returns!$O14=1,Returns!D14,"") | N14: =IF(Returns!$O14=1,Returns!E14,"") | O14: =IF(Returns!$O14=1,Returns!F14,"") | P14: =IF(Returns!$O14=1,Returns!G14,"") | Q14: =IF(Returns!$O14=1,Returns!H14,"") | R14: =IF(Returns!$O14=1,Returns!I14,"") | S14: =IF(Returns!$O14=1,Returns!J14,"") | T14: =IF(Returns!$O14=1,"",Returns!K14) -> 0.0063140677
A15: =Returns!A15 -> 43725 | B15: =IF(Returns!$O15=1,"",Returns!B15) -> 0.018046111 | C15: =IF(Returns!$O15=1,"",Returns!C15) -> 0.024378919 | D15: =IF(Returns!$O15=1,"",Returns!D15) -> 0.0045691906 | E15: =IF(Returns!$O15=1,"",Returns!E15) -> 0.0058770573 | F15: =IF(Returns!$O15=1,"",Returns!F15) -> 0.025160643 | G15: =IF(Returns!$O15=1,"",Returns!G15) -> 0.023927041 | H15: =IF(Returns!$O15=1,"",Returns!H15) -> -0.013185959 | I15: =IF(Returns!$O15=1,"",Returns!I15) -> 0.0069611012 | J15: =IF(Returns!$O15=1,"",Returns!J15) -> 0.0063799547 | K15: =IF(Returns!$O15=1,Returns!B15,"") | L15: =IF(Returns!$O15=1,Returns!C15,"") | M15: =IF(Returns!$O15=1,Returns!D15,"") | N15: =IF(Returns!$O15=1,Returns!E15,"") | O15: =IF(Returns!$O15=1,Returns!F15,"") | P15: =IF(Returns!$O15=1,Returns!G15,"") | Q15: =IF(Returns!$O15=1,Returns!H15,"") | R15: =IF(Returns!$O15=1,Returns!I15,"") | S15: =IF(Returns!$O15=1,Returns!J15,"") | T15: =IF(Returns!$O15=1,"",Returns!K15) -> 0.011346007
... A494: =Returns!A494 -> 44435 | B494: =IF(Returns!$O494=1,"",Returns!B494) -> 0.011717028 | C494: =IF(Returns!$O494=1,"",Returns!C494) -> 0.020497804 | D494: =IF(Returns!$O494=1,"",Returns!D494) -> 0.013272582 | E494: =IF(Returns!$O494=1,"",Returns!E494) -> 0.041815583 | F494: =IF(Returns!$O494=1,"",Returns!F494) -> 0 | G494: =IF(Returns!$O494=1,"",Returns!G494) -> 0.019458946 | H494: =IF(Returns!$O494=1,"",Returns!H494) -> 0.036376864 | I494: =IF(Returns!$O494=1,"",Returns!I494) -> 0.010245867 | J494: =IF(Returns!$O494=1,"",Returns!J494) -> 0.025043255 | K494: =IF(Returns!$O494=1,Returns!B494,"") | L494: =IF(Returns!$O494=1,Returns!C494,"") | M494: =IF(Returns!$O494=1,Returns!D494,"") | N494: =IF(Returns!$O494=1,Returns!E494,"") | O494: =IF(Returns!$O494=1,Returns!F494,"") | P494: =IF(Returns!$O494=1,Returns!G494,"") | Q494: =IF(Returns!$O494=1,Returns!H494,"") | R494: =IF(Returns!$O494=1,Returns!I494,"") | S494: =IF(Returns!$O494=1,Returns!J494,"") | T494: =IF(Returns!$O494=1,"",Returns!K494) -> 0.019825326

Sheet Risk_Metrics
A1: Risk metrics: equal-weight portfolio
A2: VaR and Expected Shortfall use the historical method (percentile of actual daily returns).
B3: 1. Portfolio risk, full period
B5: Daily volatility (standard deviation) | C5: =STDEV(Returns!$K$4:$K$494) -> 0.02360074 | D5: STDEV is the sample standard deviation.
B6: Annualised volatility | C6: =C5*SQRT(Inputs!$C$8) -> 0.37465013
B7: VaR 95% (historical) | C7: =PERCENTILE(Returns!$K$4:$K$494,Inputs!$C$5) -> -0.025595079 | D7: Loss exceeded only on the worst 5% of days.
B8: Expected Shortfall 95% | C8: =AVERAGEIF(Returns!$K$4:$K$494,"<="&C7) -> -0.060811559 | D8: Average loss on the days that exceed the VaR.
B9: VaR 95% (R$) | C9: =C7*Inputs!$C$4 -> -25595.079
B10: Expected Shortfall 95% (R$) | C10: =C8*Inputs!$C$4 -> -60811.559
B11: Number of daily returns | C11: =COUNT(Returns!$K$4:$K$494) -> 491
B12: Days in the tail (return <= VaR) | C12: =COUNTIF(Returns!$K$4:$K$494,"<="&C7) -> 25
B14: 2. Weight of the crash window (Feb-Apr 2020)
B16: Days inside the crash window | C16: =SUM(Returns!$O$4:$O$494) -> 46
B17: Share of all days | C17: =C16/C11 -> 0.093686354
B18: Tail days that fall inside the crash window | C18: =COUNTIFS(Returns!$K$4:$K$494,"<="&C7,Returns!$O$4:$O$494,1) -> 14
B19: Share of tail days inside the crash window | C19: =C18/C12 -> 0.56 | D19: A small share of days concentrates most of the worst days.
B20: VaR 95% excluding the crash window | C20: =PERCENTILE(Returns_Helper!$T$4:$T$494,Inputs!$C$5) -> -0.019974351
B21: Expected Shortfall 95% excluding the crash window | C21: =AVERAGEIF(Returns_Helper!$T$4:$T$494,"<="&C20) -> -0.029953101
B22: Days used excluding the crash window | C22: =COUNT(Returns_Helper!$T$4:$T$494) -> 445
B23: Change in Expected Shortfall without the crash | C23: =C21/C8-1 -> -0.50744396
B25: 3. Drawdown of the equal-weight portfolio
B27: Maximum drawdown | C27: =MIN(Returns!$R$4:$R$494) -> -0.47234663
B28: Trough date | C28: =INDEX(Returns!$A$4:$A$494,E28) -> 43908 | E28: =MATCH(C27,Returns!$R$4:$R$494,0) -> 134 | F28: <- position of the trough in the Returns table (helper)
B29: Index at trough | C29: =INDEX(Returns!$P$4:$P$494,MATCH(C28,Returns!$A$4:$A$494,0)) -> 68.621836
B30: Peak index before the trough | C30: =INDEX(Returns!$Q$4:$Q$494,MATCH(C28,Returns!$A$4:$A$494,0)) -> 130.05098
B31: Peak date | C31: =INDEX(Returns!$A$4:$A$494,MATCH(C30,Returns!$P$4:$P$494,0)) -> 43853
B32: Date the previous peak was recovered | C32: =INDEX(Returns!$A$4:$A$494,MATCH(1,Returns!$T$4:$T$494,0)) -> 44158
B34: 4. Risk by stock (daily returns)
B35: Stock | C35: Weight (equal) | D35: Daily volatility | E35: Annualised volatility | F35: VaR 95% | G35: Expected Shortfall 95%
B36: Arezzo&Co | C36: =Optimization!C7 -> 0.11111111 | D36: =STDEV(Returns!$B$4:$B$494) -> 0.030045982 | E36: =D36*SQRT(Inputs!$C$8) -> 0.47696518 | F36: =PERCENTILE(Returns!$B$4:$B$494,Inputs!$C$5) -> -0.03798694 | G36: =AVERAGEIF(Returns!$B$4:$B$494,"<="&F36) -> -0.068564628
B37: B3 | C37: =Optimization!D7 -> 0.11111111 | D37: =STDEV(Returns!$C$4:$C$494) -> 0.029321309 | E37: =D37*SQRT(Inputs!$C$8) -> 0.46546135 | F37: =PERCENTILE(Returns!$C$4:$C$494,Inputs!$C$5) -> -0.038887382 | G37: =AVERAGEIF(Returns!$C$4:$C$494,"<="&F37) -> -0.066606275
B38: Klabin | C38: =Optimization!E7 -> 0.11111111 | D38: =STDEV(Returns!$D$4:$D$494) -> 0.024450549 | E38: =D38*SQRT(Inputs!$C$8) -> 0.38814043 | F38: =PERCENTILE(Returns!$D$4:$D$494,Inputs!$C$5) -> -0.028584345 | G38: =AVERAGEIF(Returns!$D$4:$D$494,"<="&F38) -> -0.055275423
B39: Localiza | C39: =Optimization!F7 -> 0.11111111 | D39: =STDEV(Returns!$E$4:$E$494) -> 0.037241516 | E39: =D39*SQRT(Inputs!$C$8) -> 0.59119073 | F39: =PERCENTILE(Returns!$E$4:$E$494,Inputs!$C$5) -> -0.051236696 | G39: =AVERAGEIF(Returns!$E$4:$E$494,"<="&F39) -> -0.089922145
B40: Lojas Americanas | C40: =Optimization!G7 -> 0.11111111 | D40: =STDEV(Returns!$F$4:$F$494) -> 0.044136992 | E40: =D40*SQRT(Inputs!$C$8) -> 0.70065303 | F40: =PERCENTILE(Returns!$F$4:$F$494,Inputs!$C$5) -> -0.051956318 | G40: =AVERAGEIF(Returns!$F$4:$F$494,"<="&F40) -> -0.10145779
B41: Multiplan | C41: =Optimization!H7 -> 0.11111111 | D41: =STDEV(Returns!$G$4:$G$494) -> 0.033549717 | E41: =D41*SQRT(Inputs!$C$8) -> 0.53258525 | F41: =PERCENTILE(Returns!$G$4:$G$494,Inputs!$C$5) -> -0.04226247 | G41: =AVERAGEIF(Returns!$G$4:$G$494,"<="&F41) -> -0.07516982
B42: Petrobras | C42: =Optimization!I7 -> 0.11111111 | D42: =STDEV(Returns!$H$4:$H$494) -> 0.035736886 | E42: =D42*SQRT(Inputs!$C$8) -> 0.56730547 | F42: =PERCENTILE(Returns!$H$4:$H$494,Inputs!$C$5) -> -0.040597097 | G42: =AVERAGEIF(Returns!$H$4:$H$494,"<="&F42) -> -0.08792858
B43: SulAmerica | C43: =Optimization!J7 -> 0.11111111 | D43: =STDEV(Returns!$I$4:$I$494) -> 0.028871642 | E43: =D43*SQRT(Inputs!$C$8) -> 0.45832311 | F43: =PERCENTILE(Returns!$I$4:$I$494,Inputs!$C$5) -> -0.037583693 | G43: =AVERAGEIF(Returns!$I$4:$I$494,"<="&F43) -> -0.066243647
B44: Vale | C44: =Optimization!K7 -> 0.11111111 | D44: =STDEV(Returns!$J$4:$J$494) -> 0.028569165 | E44: =D44*SQRT(Inputs!$C$8) -> 0.45352143 | F44: =PERCENTILE(Returns!$J$4:$J$494,Inputs!$C$5) -> -0.034064382 | G44: =AVERAGEIF(Returns!$J$4:$J$494,"<="&F44) -> -0.059896282
B45: Average of the 9 stocks | D45: =AVERAGE(D36:D44) -> 0.032435973
B46: Equal-weight portfolio | D46: =C5 -> 0.02360074
...

Sheet Correlation
A1: Correlation matrices (Pearson, daily returns)
A2: Excluding / crash-only matrices use helper series; Excel ignores the blank cells pair-wise.
B3: 1. Full period
C4: Arezzo&Co | D4: B3 | E4: Klabin | F4: Localiza | G4: Lojas Americanas | H4: Multiplan | I4: Petrobras | J4: SulAmerica | K4: Vale
B5: Arezzo&Co | C5: =CORREL(Returns!$B$4:$B$494,Returns!$B$4:$B$494) -> 1 | D5: =CORREL(Returns!$B$4:$B$494,Returns!$C$4:$C$494) -> 0.51536966 | E5: =CORREL(Returns!$B$4:$B$494,Returns!$D$4:$D$494) -> 0.26735187 | F5: =CORREL(Returns!$B$4:$B$494,Returns!$E$4:$E$494) -> 0.60912984 | G5: =CORREL(Returns!$B$4:$B$494,Returns!$F$4:$F$494) -> 0.41946243 | H5: =CORREL(Returns!$B$4:$B$494,Returns!$G$4:$G$494) -> 0.57372709 | I5: =CORREL(Returns!$B$4:$B$494,Returns!$H$4:$H$494) -> 0.46475221 | J5: =CORREL(Returns!$B$4:$B$494,Returns!$I$4:$I$494) -> 0.58781375 | K5: =CORREL(Returns!$B$4:$B$494,Returns!$J$4:$J$494) -> 0.36636425
B6: B3 | C6: =CORREL(Returns!$C$4:$C$494,Returns!$B$4:$B$494) -> 0.51536966 | D6: =CORREL(Returns!$C$4:$C$494,Returns!$C$4:$C$494) -> 1 | E6: =CORREL(Returns!$C$4:$C$494,Returns!$D$4:$D$494) -> 0.27960202 | F6: =CORREL(Returns!$C$4:$C$494,Returns!$E$4:$E$494) -> 0.61477861 | G6: =CORREL(Returns!$C$4:$C$494,Returns!$F$4:$F$494) -> 0.40107432 | H6: =CORREL(Returns!$C$4:$C$494,Returns!$G$4:$G$494) -> 0.59127159 | I6: =CORREL(Returns!$C$4:$C$494,Returns!$H$4:$H$494) -> 0.58653979 | J6: =CORREL(Returns!$C$4:$C$494,Returns!$I$4:$I$494) -> 0.5903795 | K6: =CORREL(Returns!$C$4:$C$494,Returns!$J$4:$J$494) -> 0.49653525
B7: Klabin | C7: =CORREL(Returns!$D$4:$D$494,Returns!$B$4:$B$494) -> 0.26735187 | D7: =CORREL(Returns!$D$4:$D$494,Returns!$C$4:$C$494) -> 0.27960202 | E7: =CORREL(Returns!$D$4:$D$494,Returns!$D$4:$D$494) -> 1 | F7: =CORREL(Returns!$D$4:$D$494,Returns!$E$4:$E$494) -> 0.24191524 | G7: =CORREL(Returns!$D$4:$D$494,Returns!$F$4:$F$494) -> 0.26594161 | H7: =CORREL(Returns!$D$4:$D$494,Returns!$G$4:$G$494) -> 0.29980858 | I7: =CORREL(Returns!$D$4:$D$494,Returns!$H$4:$H$494) -> 0.35058211 | J7: =CORREL(Returns!$D$4:$D$494,Returns!$I$4:$I$494) -> 0.32907264 | K7: =CORREL(Returns!$D$4:$D$494,Returns!$J$4:$J$494) -> 0.37429532
B8: Localiza | C8: =CORREL(Returns!$E$4:$E$494,Returns!$B$4:$B$494) -> 0.60912984 | D8: =CORREL(Returns!$E$4:$E$494,Returns!$C$4:$C$494) -> 0.61477861 | E8: =CORREL(Returns!$E$4:$E$494,Returns!$D$4:$D$494) -> 0.24191524 | F8: =CORREL(Returns!$E$4:$E$494,Returns!$E$4:$E$494) -> 1 | G8: =CORREL(Returns!$E$4:$E$494,Returns!$F$4:$F$494) -> 0.43966321 | H8: =CORREL(Returns!$E$4:$E$494,Returns!$G$4:$G$494) -> 0.65767734 | I8: =CORREL(Returns!$E$4:$E$494,Returns!$H$4:$H$494) -> 0.55583161 | J8: =CORREL(Returns!$E$4:$E$494,Returns!$I$4:$I$494) -> 0.63289141 | K8: =CORREL(Returns!$E$4:$E$494,Returns!$J$4:$J$494) -> 0.41928893
B9: Lojas Americanas | C9: =CORREL(Returns!$F$4:$F$494,Returns!$B$4:$B$494) -> 0.41946243 | D9: =CORREL(Returns!$F$4:$F$494,Returns!$C$4:$C$494) -> 0.40107432 | E9: =CORREL(Returns!$F$4:$F$494,Returns!$D$4:$D$494) -> 0.26594161 | F9: =CORREL(Returns!$F$4:$F$494,Returns!$E$4:$E$494) -> 0.43966321 | G9: =CORREL(Returns!$F$4:$F$494,Returns!$F$4:$F$494) -> 1 | H9: =CORREL(Returns!$F$4:$F$494,Returns!$G$4:$G$494) -> 0.42679142 | I9: =CORREL(Returns!$F$4:$F$494,Returns!$H$4:$H$494) -> 0.35153064 | J9: =CORREL(Returns!$F$4:$F$494,Returns!$I$4:$I$494) -> 0.46098575 | K9: =CORREL(Returns!$F$4:$F$494,Returns!$J$4:$J$494) -> 0.29856559
B10: Multiplan | C10: =CORREL(Returns!$G$4:$G$494,Returns!$B$4:$B$494) -> 0.57372709 | D10: =CORREL(Returns!$G$4:$G$494,Returns!$C$4:$C$494) -> 0.59127159 | E10: =CORREL(Returns!$G$4:$G$494,Returns!$D$4:$D$494) -> 0.29980858 | F10: =CORREL(Returns!$G$4:$G$494,Returns!$E$4:$E$494) -> 0.65767734 | G10: =CORREL(Returns!$G$4:$G$494,Returns!$F$4:$F$494) -> 0.42679142 | H10: =CORREL(Returns!$G$4:$G$494,Returns!$G$4:$G$494) -> 1 | I10: =CORREL(Returns!$G$4:$G$494,Returns!$H$4:$H$494) -> 0.57384469 | J10: =CORREL(Returns!$G$4:$G$494,Returns!$I$4:$I$494) -> 0.63399694 | K10: =CORREL(Returns!$G$4:$G$494,Returns!$J$4:$J$494) -> 0.40076329
B11: Petrobras | C11: =CORREL(Returns!$H$4:$H$494,Returns!$B$4:$B$494) -> 0.46475221 | D11: =CORREL(Returns!$H$4:$H$494,Returns!$C$4:$C$494) -> 0.58653979 | E11: =CORREL(Returns!$H$4:$H$494,Returns!$D$4:$D$494) -> 0.35058211 | F11: =CORREL(Returns!$H$4:$H$494,Returns!$E$4:$E$494) -> 0.55583161 | G11: =CORREL(Returns!$H$4:$H$494,Returns!$F$4:$F$494) -> 0.35153064 | H11: =CORREL(Returns!$H$4:$H$494,Returns!$G$4:$G$494) -> 0.57384469 | I11: =CORREL(Returns!$H$4:$H$494,Returns!$H$4:$H$494) -> 1 | J11: =CORREL(Returns!$H$4:$H$494,Returns!$I$4:$I$494) -> 0.57286659 | K11: =CORREL(Returns!$H$4:$H$494,Returns!$J$4:$J$494) -> 0.62644189
B12: SulAmerica | C12: =CORREL(Returns!$I$4:$I$494,Returns!$B$4:$B$494) -> 0.58781375 | D12: =CORREL(Returns!$I$4:$I$494,Returns!$C$4:$C$494) -> 0.5903795 | E12: =CORREL(Returns!$I$4:$I$494,Returns!$D$4:$D$494) -> 0.32907264 | F12: =CORREL(Returns!$I$4:$I$494,Returns!$E$4:$E$494) -> 0.63289141 | G12: =CORREL(Returns!$I$4:$I$494,Returns!$F$4:$F$494) -> 0.46098575 | H12: =CORREL(Returns!$I$4:$I$494,Returns!$G$4:$G$494) -> 0.63399694 | I12: =CORREL(Returns!$I$4:$I$494,Returns!$H$4:$H$494) -> 0.57286659 | J12: =CORREL(Returns!$I$4:$I$494,Returns!$I$4:$I$494) -> 1 | K12: =CORREL(Returns!$I$4:$I$494,Returns!$J$4:$J$494) -> 0.43662949
B13: Vale | C13: =CORREL(Returns!$J$4:$J$494,Returns!$B$4:$B$494) -> 0.36636425 | D13: =CORREL(Returns!$J$4:$J$494,Returns!$C$4:$C$494) -> 0.49653525 | E13: =CORREL(Returns!$J$4:$J$494,Returns!$D$4:$D$494) -> 0.37429532 | F13: =CORREL(Returns!$J$4:$J$494,Returns!$E$4:$E$494) -> 0.41928893 | G13: =CORREL(Returns!$J$4:$J$494,Returns!$F$4:$F$494) -> 0.29856559 | H13: =CORREL(Returns!$J$4:$J$494,Returns!$G$4:$G$494) -> 0.40076329 | I13: =CORREL(Returns!$J$4:$J$494,Returns!$H$4:$H$494) -> 0.62644189 | J13: =CORREL(Returns!$J$4:$J$494,Returns!$I$4:$I$494) -> 0.43662949 | K13: =CORREL(Returns!$J$4:$J$494,Returns!$J$4:$J$494) -> 1
B14: Average pair correlation | C14: =(SUM(C5:K13)-9)/(9*(9-1)) -> 0.4642649
B17: 2. Excluding the crash window (Feb-Apr 2020)
C18: Arezzo&Co | D18: B3 | E18: Klabin | F18: Localiza | G18: Lojas Americanas | H18: Multiplan | I18: Petrobras | J18: SulAmerica | K18: Vale
B19: Arezzo&Co | C19: =CORREL(Returns_Helper!$B$4:$B$494,Returns_Helper!$B$4:$B$494) -> 1 | D19: =CORREL(Returns_Helper!$B$4:$B$494,Returns_Helper!$C$4:$C$494) -> 0.33333559 | E19: =CORREL(Returns_Helper!$B$4:$B$494,Returns_Helper!$D$4:$D$494) -> 0.068360195 | F19: =CORREL(Returns_Helper!$B$4:$B$494,Returns_Helper!$E$4:$E$494) -> 0.30956612 | G19: =CORREL(Returns_Helper!$B$4:$B$494,Returns_Helper!$F$4:$F$494) -> 0.24296867 | H19: =CORREL(Returns_Helper!$B$4:$B$494,Returns_Helper!$G$4:$G$494) -> 0.34268994 | I19: =CORREL(Returns_Helper!$B$4:$B$494,Returns_Helper!$H$4:$H$494) -> 0.21466309 | J19: =CORREL(Returns_Helper!$B$4:$B$494,Returns_Helper!$I$4:$I$494) -> 0.32437566 | K19: =CORREL(Returns_Helper!$B$4:$B$494,Returns_Helper!$J$4:$J$494) -> 0.081225351
B20: B3 | C20: =CORREL(Returns_Helper!$C$4:$C$494,Returns_Helper!$B$4:$B$494) -> 0.33333559 | D20: =CORREL(Returns_Helper!$C$4:$C$494,Returns_Helper!$C$4:$C$494) -> 1 | E20: =CORREL(Returns_Helper!$C$4:$C$494,Returns_Helper!$D$4:$D$494) -> 0.05470817 | F20: =CORREL(Returns_Helper!$C$4:$C$494,Returns_Helper!$E$4:$E$494) -> 0.4464921 | G20: =CORREL(Returns_Helper!$C$4:$C$494,Returns_Helper!$F$4:$F$494) -> 0.16747323 | H20: =CORREL(Returns_Helper!$C$4:$C$494,Returns_Helper!$G$4:$G$494) -> 0.38415427 | I20: =CORREL(Returns_Helper!$C$4:$C$494,Returns_Helper!$H$4:$H$494) -> 0.31946833 | J20: =CORREL(Returns_Helper!$C$4:$C$494,Returns_Helper!$I$4:$I$494) -> 0.37205344 | K20: =CORREL(Returns_Helper!$C$4:$C$494,Returns_Helper!$J$4:$J$494) -> 0.19601448
B21: Klabin | C21: =CORREL(Returns_Helper!$D$4:$D$494,Returns_Helper!$B$4:$B$494) -> 0.068360195 | D21: =CORREL(Returns_Helper!$D$4:$D$494,Returns_Helper!$C$4:$C$494) -> 0.05470817 | E21: =CORREL(Returns_Helper!$D$4:$D$494,Returns_Helper!$D$4:$D$494) -> 1 | F21: =CORREL(Returns_Helper!$D$4:$D$494,Returns_Helper!$E$4:$E$494) -> -0.0043596409 | G21: =CORREL(Returns_Helper!$D$4:$D$494,Returns_Helper!$F$4:$F$494) -> 0.1255141 | H21: =CORREL(Returns_Helper!$D$4:$D$494,Returns_Helper!$G$4:$G$494) -> 0.050302954 | I21: =CORREL(Returns_Helper!$D$4:$D$494,Returns_Helper!$H$4:$H$494) -> 0.071938524 | J21: =CORREL(Returns_Helper!$D$4:$D$494,Returns_Helper!$I$4:$I$494) -> 0.11340902 | K21: =CORREL(Returns_Helper!$D$4:$D$494,Returns_Helper!$J$4:$J$494) -> 0.26520241
B22: Localiza | C22: =CORREL(Returns_Helper!$E$4:$E$494,Returns_Helper!$B$4:$B$494) -> 0.30956612 | D22: =CORREL(Returns_Helper!$E$4:$E$494,Returns_Helper!$C$4:$C$494) -> 0.4464921 | E22: =CORREL(Returns_Helper!$E$4:$E$494,Returns_Helper!$D$4:$D$494) -> -0.0043596409 | F22: =CORREL(Returns_Helper!$E$4:$E$494,Returns_Helper!$E$4:$E$494) -> 1 | G22: =CORREL(Returns_Helper!$E$4:$E$494,Returns_Helper!$F$4:$F$494) -> 0.2343579 | H22: =CORREL(Returns_Helper!$E$4:$E$494,Returns_Helper!$G$4:$G$494) -> 0.42899289 | I22: =CORREL(Returns_Helper!$E$4:$E$494,Returns_Helper!$H$4:$H$494) -> 0.34271587 | J22: =CORREL(Returns_Helper!$E$4:$E$494,Returns_Helper!$I$4:$I$494) -> 0.33235943 | K22: =CORREL(Returns_Helper!$E$4:$E$494,Returns_Helper!$J$4:$J$494) -> 0.1887181
B23: Lojas Americanas | C23: =CORREL(Returns_Helper!$F$4:$F$494,Returns_Helper!$B$4:$B$494) -> 0.24296867 | D23: =CORREL(Returns_Helper!$F$4:$F$494,Returns_Helper!$C$4:$C$494) -> 0.16747323 | E23: =CORREL(Returns_Helper!$F$4:$F$494,Returns_Helper!$D$4:$D$494) -> 0.1255141 | F23: =CORREL(Returns_Helper!$F$4:$F$494,Returns_Helper!$E$4:$E$494) -> 0.2343579 | G23: =CORREL(Returns_Helper!$F$4:$F$494,Returns_Helper!$F$4:$F$494) -> 1 | H23: =CORREL(Returns_Helper!$F$4:$F$494,Returns_Helper!$G$4:$G$494) -> 0.25324335 | I23: =CORREL(Returns_Helper!$F$4:$F$494,Returns_Helper!$H$4:$H$494) -> 0.07848009 | J23: =CORREL(Returns_Helper!$F$4:$F$494,Returns_Helper!$I$4:$I$494) -> 0.24055806 | K23: =CORREL(Returns_Helper!$F$4:$F$494,Returns_Helper!$J$4:$J$494) -> 0.039141618
B24: Multiplan | C24: =CORREL(Returns_Helper!$G$4:$G$494,Returns_Helper!$B$4:$B$494) -> 0.34268994 | D24: =CORREL(Returns_Helper!$G$4:$G$494,Returns_Helper!$C$4:$C$494) -> 0.38415427 | E24: =CORREL(Returns_Helper!$G$4:$G$494,Returns_Helper!$D$4:$D$494) -> 0.050302954 | F24: =CORREL(Returns_Helper!$G$4:$G$494,Returns_Helper!$E$4:$E$494) -> 0.42899289 | G24: =CORREL(Returns_Helper!$G$4:$G$494,Returns_Helper!$F$4:$F$494) -> 0.25324335 | H24: =CORREL(Returns_Helper!$G$4:$G$494,Returns_Helper!$G$4:$G$494) -> 1 | I24: =CORREL(Returns_Helper!$G$4:$G$494,Returns_Helper!$H$4:$H$494) -> 0.38458508 | J24: =CORREL(Returns_Helper!$G$4:$G$494,Returns_Helper!$I$4:$I$494) -> 0.42007171 | K24: =CORREL(Returns_Helper!$G$4:$G$494,Returns_Helper!$J$4:$J$494) -> 0.17156112
B25: Petrobras | C25: =CORREL(Returns_Helper!$H$4:$H$494,Returns_Helper!$B$4:$B$494) -> 0.21466309 | D25: =CORREL(Returns_Helper!$H$4:$H$494,Returns_Helper!$C$4:$C$494) -> 0.31946833 | E25: =CORREL(Returns_Helper!$H$4:$H$494,Returns_Helper!$D$4:$D$494) -> 0.071938524 | F25: =CORREL(Returns_Helper!$H$4:$H$494,Returns_Helper!$E$4:$E$494) -> 0.34271587 | G25: =CORREL(Returns_Helper!$H$4:$H$494,Returns_Helper!$F$4:$F$494) -> 0.07848009 | H25: =CORREL(Returns_Helper!$H$4:$H$494,Returns_Helper!$G$4:$G$494) -> 0.38458508 | I25: =CORREL(Returns_Helper!$H$4:$H$494,Returns_Helper!$H$4:$H$494) -> 1 | J25: =CORREL(Returns_Helper!$H$4:$H$494,Returns_Helper!$I$4:$I$494) -> 0.28397147 | K25: =CORREL(Returns_Helper!$H$4:$H$494,Returns_Helper!$J$4:$J$494) -> 0.37269609
B26: SulAmerica | C26: =CORREL(Returns_Helper!$I$4:$I$494,Returns_Helper!$B$4:$B$494) -> 0.32437566 | D26: =CORREL(Returns_Helper!$I$4:$I$494,Returns_Helper!$C$4:$C$494) -> 0.37205344 | E26: =CORREL(Returns_Helper!$I$4:$I$494,Returns_Helper!$D$4:$D$494) -> 0.11340902 | F26: =CORREL(Returns_Helper!$I$4:$I$494,Returns_Helper!$E$4:$E$494) -> 0.33235943 | G26: =CORREL(Returns_Helper!$I$4:$I$494,Returns_Helper!$F$4:$F$494) -> 0.24055806 | H26: =CORREL(Returns_Helper!$I$4:$I$494,Returns_Helper!$G$4:$G$494) -> 0.42007171 | I26: =CORREL(Returns_Helper!$I$4:$I$494,Returns_Helper!$H$4:$H$494) -> 0.28397147 | J26: =CORREL(Returns_Helper!$I$4:$I$494,Returns_Helper!$I$4:$I$494) -> 1 | K26: =CORREL(Returns_Helper!$I$4:$I$494,Returns_Helper!$J$4:$J$494) -> 0.12511111
B27: Vale | C27: =CORREL(Returns_Helper!$J$4:$J$494,Returns_Helper!$B$4:$B$494) -> 0.081225351 | D27: =CORREL(Returns_Helper!$J$4:$J$494,Returns_Helper!$C$4:$C$494) -> 0.19601448 | E27: =CORREL(Returns_Helper!$J$4:$J$494,Returns_Helper!$D$4:$D$494) -> 0.26520241 | F27: =CORREL(Returns_Helper!$J$4:$J$494,Returns_Helper!$E$4:$E$494) -> 0.1887181 | G27: =CORREL(Returns_Helper!$J$4:$J$494,Returns_Helper!$F$4:$F$494) -> 0.039141618 | H27: =CORREL(Returns_Helper!$J$4:$J$494,Returns_Helper!$G$4:$G$494) -> 0.17156112 | I27: =CORREL(Returns_Helper!$J$4:$J$494,Returns_Helper!$H$4:$H$494) -> 0.37269609 | J27: =CORREL(Returns_Helper!$J$4:$J$494,Returns_Helper!$I$4:$I$494) -> 0.12511111 | K27: =CORREL(Returns_Helper!$J$4:$J$494,Returns_Helper!$J$4:$J$494) -> 1
B28: Average pair correlation | C28: =(SUM(C19:K27)-9)/(9*(9-1)) -> 0.23267
B31: 3. Crash window only (Feb-Apr 2020)
C32: Arezzo&Co | D32: B3 | E32: Klabin | F32: Localiza | G32: Lojas Americanas | H32: Multiplan | I32: Petrobras | J32: SulAmerica | K32: Vale
B33: Arezzo&Co | C33: =CORREL(Returns_Helper!$K$4:$K$494,Returns_Helper!$K$4:$K$494) -> 1 | D33: =CORREL(Returns_Helper!$K$4:$K$494,Returns_Helper!$L$4:$L$494) -> 0.71924108 | E33: =CORREL(Returns_Helper!$K$4:$K$494,Returns_Helper!$M$4:$M$494) -> 0.50385001 | F33: =CORREL(Returns_Helper!$K$4:$K$494,Returns_Helper!$N$4:$N$494) -> 0.87954121 | G33: =CORREL(Returns_Helper!$K$4:$K$494,Returns_Helper!$O$4:$O$494) -> 0.75346195 | H33: =CORREL(Returns_Helper!$K$4:$K$494,Returns_Helper!$P$4:$P$494) -> 0.81944775 | I33: =CORREL(Returns_Helper!$K$4:$K$494,Returns_Helper!$Q$4:$Q$494) -> 0.69717944 | J33: =CORREL(Returns_Helper!$K$4:$K$494,Returns_Helper!$R$4:$R$494) -> 0.84590939 | K33: =CORREL(Returns_Helper!$K$4:$K$494,Returns_Helper!$S$4:$S$494) -> 0.64689206
B34: B3 | C34: =CORREL(Returns_Helper!$L$4:$L$494,Returns_Helper!$K$4:$K$494) -> 0.71924108 | D34: =CORREL(Returns_Helper!$L$4:$L$494,Returns_Helper!$L$4:$L$494) -> 1 | E34: =CORREL(Returns_Helper!$L$4:$L$494,Returns_Helper!$M$4:$M$494) -> 0.55634561 | F34: =CORREL(Returns_Helper!$L$4:$L$494,Returns_Helper!$N$4:$N$494) -> 0.77467133 | G34: =CORREL(Returns_Helper!$L$4:$L$494,Returns_Helper!$O$4:$O$494) -> 0.83332014 | H34: =CORREL(Returns_Helper!$L$4:$L$494,Returns_Helper!$P$4:$P$494) -> 0.81891486 | I34: =CORREL(Returns_Helper!$L$4:$L$494,Returns_Helper!$Q$4:$Q$494) -> 0.84670734 | J34: =CORREL(Returns_Helper!$L$4:$L$494,Returns_Helper!$R$4:$R$494) -> 0.81026552 | K34: =CORREL(Returns_Helper!$L$4:$L$494,Returns_Helper!$S$4:$S$494) -> 0.80154863
B35: Klabin | C35: =CORREL(Returns_Helper!$M$4:$M$494,Returns_Helper!$K$4:$K$494) -> 0.50385001 | D35: =CORREL(Returns_Helper!$M$4:$M$494,Returns_Helper!$L$4:$L$494) -> 0.55634561 | E35: =CORREL(Returns_Helper!$M$4:$M$494,Returns_Helper!$M$4:$M$494) -> 1 | F35: =CORREL(Returns_Helper!$M$4:$M$494,Returns_Helper!$N$4:$N$494) -> 0.48212929 | G35: =CORREL(Returns_Helper!$M$4:$M$494,Returns_Helper!$O$4:$O$494) -> 0.54021552 | H35: =CORREL(Returns_Helper!$M$4:$M$494,Returns_Helper!$P$4:$P$494) -> 0.59166802 | I35: =CORREL(Returns_Helper!$M$4:$M$494,Returns_Helper!$Q$4:$Q$494) -> 0.63882031 | J35: =CORREL(Returns_Helper!$M$4:$M$494,Returns_Helper!$R$4:$R$494) -> 0.55995994 | K35: =CORREL(Returns_Helper!$M$4:$M$494,Returns_Helper!$S$4:$S$494) -> 0.49402028
B36: Localiza | C36: =CORREL(Returns_Helper!$N$4:$N$494,Returns_Helper!$K$4:$K$494) -> 0.87954121 | D36: =CORREL(Returns_Helper!$N$4:$N$494,Returns_Helper!$L$4:$L$494) -> 0.77467133 | E36: =CORREL(Returns_Helper!$N$4:$N$494,Returns_Helper!$M$4:$M$494) -> 0.48212929 | F36: =CORREL(Returns_Helper!$N$4:$N$494,Returns_Helper!$N$4:$N$494) -> 1 | G36: =CORREL(Returns_Helper!$N$4:$N$494,Returns_Helper!$O$4:$O$494) -> 0.7764698 | H36: =CORREL(Returns_Helper!$N$4:$N$494,Returns_Helper!$P$4:$P$494) -> 0.85879276 | I36: =CORREL(Returns_Helper!$N$4:$N$494,Returns_Helper!$Q$4:$Q$494) -> 0.71258379 | J36: =CORREL(Returns_Helper!$N$4:$N$494,Returns_Helper!$R$4:$R$494) -> 0.86556469 | K36: =CORREL(Returns_Helper!$N$4:$N$494,Returns_Helper!$S$4:$S$494) -> 0.59940306
B37: Lojas Americanas | C37: =CORREL(Returns_Helper!$O$4:$O$494,Returns_Helper!$K$4:$K$494) -> 0.75346195 | D37: =CORREL(Returns_Helper!$O$4:$O$494,Returns_Helper!$L$4:$L$494) -> 0.83332014 | E37: =CORREL(Returns_Helper!$O$4:$O$494,Returns_Helper!$M$4:$M$494) -> 0.54021552 | F37: =CORREL(Returns_Helper!$O$4:$O$494,Returns_Helper!$N$4:$N$494) -> 0.7764698 | G37: =CORREL(Returns_Helper!$O$4:$O$494,Returns_Helper!$O$4:$O$494) -> 1 | H37: =CORREL(Returns_Helper!$O$4:$O$494,Returns_Helper!$P$4:$P$494) -> 0.74803564 | I37: =CORREL(Returns_Helper!$O$4:$O$494,Returns_Helper!$Q$4:$Q$494) -> 0.78628562 | J37: =CORREL(Returns_Helper!$O$4:$O$494,Returns_Helper!$R$4:$R$494) -> 0.83522388 | K37: =CORREL(Returns_Helper!$O$4:$O$494,Returns_Helper!$S$4:$S$494) -> 0.7184458
B38: Multiplan | C38: =CORREL(Returns_Helper!$P$4:$P$494,Returns_Helper!$K$4:$K$494) -> 0.81944775 | D38: =CORREL(Returns_Helper!$P$4:$P$494,Returns_Helper!$L$4:$L$494) -> 0.81891486 | E38: =CORREL(Returns_Helper!$P$4:$P$494,Returns_Helper!$M$4:$M$494) -> 0.59166802 | F38: =CORREL(Returns_Helper!$P$4:$P$494,Returns_Helper!$N$4:$N$494) -> 0.85879276 | G38: =CORREL(Returns_Helper!$P$4:$P$494,Returns_Helper!$O$4:$O$494) -> 0.74803564 | H38: =CORREL(Returns_Helper!$P$4:$P$494,Returns_Helper!$P$4:$P$494) -> 1 | I38: =CORREL(Returns_Helper!$P$4:$P$494,Returns_Helper!$Q$4:$Q$494) -> 0.745886 | J38: =CORREL(Returns_Helper!$P$4:$P$494,Returns_Helper!$R$4:$R$494) -> 0.83711826 | K38: =CORREL(Returns_Helper!$P$4:$P$494,Returns_Helper!$S$4:$S$494) -> 0.61953555
B39: Petrobras | C39: =CORREL(Returns_Helper!$Q$4:$Q$494,Returns_Helper!$K$4:$K$494) -> 0.69717944 | D39: =CORREL(Returns_Helper!$Q$4:$Q$494,Returns_Helper!$L$4:$L$494) -> 0.84670734 | E39: =CORREL(Returns_Helper!$Q$4:$Q$494,Returns_Helper!$M$4:$M$494) -> 0.63882031 | F39: =CORREL(Returns_Helper!$Q$4:$Q$494,Returns_Helper!$N$4:$N$494) -> 0.71258379 | G39: =CORREL(Returns_Helper!$Q$4:$Q$494,Returns_Helper!$O$4:$O$494) -> 0.78628562 | H39: =CORREL(Returns_Helper!$Q$4:$Q$494,Returns_Helper!$P$4:$P$494) -> 0.745886 | I39: =CORREL(Returns_Helper!$Q$4:$Q$494,Returns_Helper!$Q$4:$Q$494) -> 1 | J39: =CORREL(Returns_Helper!$Q$4:$Q$494,Returns_Helper!$R$4:$R$494) -> 0.80884741 | K39: =CORREL(Returns_Helper!$Q$4:$Q$494,Returns_Helper!$S$4:$S$494) -> 0.83749185
